// @sect3{The <code>main</code> function}

#include "ElasticProblem.hpp"

int main() {
    try
    {
        ElasticProblem<2> elastic_problem_2d;
        elastic_problem_2d.Run();
    }
    catch (std::exception &exc)
    {
        std::cerr << std::endl << std::endl
                  << "----------------------------------------------------"
                  << std::endl;
        std::cerr << "Exception on processing: " << std::endl
                  << exc.what() << std::endl
                  << "Aborting!" << std::endl
                  << "----------------------------------------------------"
                  << std::endl;

        return 1;
    }
    catch (...)
    {
        std::cerr << std::endl << std::endl
                  << "----------------------------------------------------"
                  << std::endl;
        std::cerr << "Unknown exception!" << std::endl
                  << "Aborting!" << std::endl
                  << "----------------------------------------------------"
                  << std::endl;
        return 1;
    }

}
